Workbook

Sheet Q4 Summary
A1: TOP GLOBAL FOOD AND BEVERAGES SDN BHD
A2: Forecast bank position at 31 December 2026 — Maybank & RHB
A3: From the 30 Sep forecast balances. Weekly detail in 'Q4 Weekly Cash Flow' (cash flow template layout); inputs in 'Q4 Assumptions'.
A5: RM | B5: Maybank | C5: RHB | D5: Maybank + RHB
A6: Bank balance at 1 Oct 2026 | B6: ='Q4 Assumptions'!$B$7 | C6: ='Q4 Assumptions'!$B$8 | D6: ='Q4 Weekly Cash Flow'!R76
A7: Net Cash Flow from Operations | B7: =D7-C7 | C7: ='Q4 Weekly Cash Flow'!R94+'Q4 Weekly Cash Flow'!R95 | D7: ='Q4 Weekly Cash Flow'!R41
A8: Net Cash Flow from Investing Activities | B8: =D8-C8 | C8: 0 | D8: ='Q4 Weekly Cash Flow'!R56
A9: Net Cash Flow from Financing Activities | B9: =D9-C9 | C9: 0 | D9: ='Q4 Weekly Cash Flow'!R72
A10: Transfers Maybank → RHB (payroll top-ups) | B10: =-'Q4 Weekly Cash Flow'!R97 | C10: ='Q4 Weekly Cash Flow'!R97 | D10: =B10+C10
A11: Net Cash Flow 1 Oct – 31 Dec | B11: =SUM(B7:B10) | C11: =SUM(C7:C10) | D11: =SUM(D7:D10)
A12: Forecast bank balance at 31 Dec 2026 | B12: =B6+B11 | C12: =C6+C11 | D12: =D6+D11
A13: Check vs weekly sheet (should be 0) | B13: =ROUND(B12-'Q4 Weekly Cash Flow'!R99,2) | C13: =ROUND(C12-'Q4 Weekly Cash Flow'!R98,2) | D13: =ROUND(D12-'Q4 Weekly Cash Flow'!R77,2)
A15: Key indicators
A16: Lowest weekly closing balance (Maybank + RHB) | D16: =MIN('Q4 Weekly Cash Flow'!$D$77:$Q$77)
A17: Week ending of lowest balance | D17: =INDEX('Q4 Weekly Cash Flow'!$D$11:$Q$11,MATCH(D16,'Q4 Weekly Cash Flow'!$D$77:$Q$77,0))
A18: Lowest weekly Maybank balance | B18: =MIN('Q4 Weekly Cash Flow'!$D$99:$Q$99)
A19: Outlets operating at 31 Dec (34 + new openings) | D19: ='Q4 Outlet Schedule'!C21
A20: New-outlet sales Oct–Dec | D20: ='Q4 Outlet Schedule'!W18
A21: Capex on new outlets Oct–Dec | D21: =-'Q4 Weekly Cash Flow'!R89
A23: Assumptions to confirm (yellow in 'Q4 Assumptions')
A24: 1. Existing 34 outlets: each template line runs at its September actual (1–28 Sep, Maybank) — daily lines ÷ 28 days, monthly lines once a month. One-offs (Sep licensing fee, deposits, capex, RM2M FD placement) are not repeated.
A25: 2. Wages: RM1M in the first week of each month (Maybank, 3rd) + RM475k in the week of the 25th (RHB; you said RM450k–500k), each +2% per new outlet open. Foreign workers RM920k mid-Oct and RM200k mid-Dec; bonus RM300k end-Dec.
A26: 3. Advance to related parties (RM192.7k in Sep) assumed to repeat monthly (prudent). Switch its Basis to 'Excluded' if it was one-off.
A27: 4. New outlets: RM8k/day sales; each new outlet open adds +3% to inventory purchases and +1% to branch upkeep (on the Sep daily level); rental 5% of new-outlet sales. Bebeks RM400k mid-Oct, Kopitiam RM350k on 31 Dec.
A28: 5. Deposits for 5 new outlets RM30k each (amount not given). SST Sep–Oct ≈ Jul–Aug amount, due 30 Nov.
A29: 6. Capex balance paid 45 days before grand opening (Cheras & PJ balances on 1 Oct). Pasir Gudang fully paid. ICOMSRWK excluded (GO TBD). FD excluded (matures 2027).

Sheet Sep30 Bridge
A1: TGFB — Forecast Cash Position as at 30 September 2026
A2: Bridge from actual 28 Sep balances to 30 Sep. Maybank inflow uses same-weekday September median; RHB uses average daily cash deposits.
A4: Date | B4: Bank | C4: Opening Balance | D4: Forecast Cash In | E4: Forecast Cash Out | F4: Net Cash Flow | G4: Closing Balance | H4: Basis
A5: 46293 | B5: Maybank | C5: 13269623 | D5: 0 | E5: 0 | F5: 0 | G5: 13269623 | H5: Actual closing balance 28 Sep
A6: 46294 | B6: Maybank | C6: =G5 | D6: 317348.35 | E6: 393281.82 | F6: =D6-E6 | G6: =C6+F6 | H6: Tue median inflow; remaining payment schedule incl. 28 Sep Maker carry-forward
A7: 46295 | B7: Maybank | C7: =G6 | D7: 305975.2 | E7: 1165510.3 | F7: =D7-E7 | G7: =C7+F7 | H7: Wed median inflow + RM8k Pasir Gudang opening-day sales; TGFB payment schedule
A8: 46295 | B8: Maybank Total Sep | C8: 14257278 | D8: =9377264.19+D6+D7 | E8: =10364919.54+E6+E7 | F8: =D8-E8 | G8: =C8+F8 | H8: Monthly Sep forecast after 29-30 Sep bridge
A10: 46293 | B10: RHB | C10: 14440.97 | D10: 0 | E10: 0 | F10: 0 | G10: 14440.97 | H10: Actual closing balance from RHB transaction CSV
A11: 46294 | B11: RHB | C11: =G10 | D11: 1775.7143 | E11: 0 | F11: =D11-E11 | G11: =C11+F11 | H11: Forecast using average daily cash deposits; no known scheduled RHB outflow
A12: 46295 | B12: RHB | C12: =G11 | D12: 1775.7143 | E12: 0 | F12: =D12-E12 | G12: =C12+F12 | H12: Forecast using average daily cash deposits; no known scheduled RHB outflow
A13: 46295 | B13: RHB Total Sep | C13: 35880.04 | D13: 425699.58 | E13: 443587.22 | F13: =D13-E13 | G13: =C13+F13 | H13: Monthly Sep forecast
A15: CONSOLIDATED TGFB BANK POSITION
A16: Opening balance 1 Sep 2026 | B16: 14293158
A17: Forecast closing Maybank 30 Sep | B17: =G7
A18: Forecast closing RHB 30 Sep | B18: =G12
A19: Forecast combined cash at 30 Sep | B19: =B17+B18
A21: Forecast combined Sep Net Cash Flow | B21: =B19-B16
A22: Maybank forecast 29-30 cash inflow | B22: =D6+D7
A23: Maybank forecast 29-30 cash outflow | B23: =E6+E7
A24: RHB forecast 29-30 cash inflow | B24: =D11+D12
A25: Incremental Pasir Gudang sales on 30 Sep | B25: 8000

Sheet Remaining Payments
A1: Original Date | B1: Forecast Pay Date | C1: Supplier | D1: Description | E1: Amount (RM) | F1: Payment Type | G1: Outlet | H1: Status / Note
A2: 46293 | B2: 46294 | C2: KONG FU PLUMBERS | D2: Repair water tank - Seremban | E2: 400 | F2: Interbank | G2: SEREMBAN | H2: Maker Carry to 29 Sep forecast
A3: 46293 | B3: 46294 | C3: TENAGA NASIONAL BERHAD | D3: TNB Sep - Segamat 40 outlet | E3: 4607.95 | F3: JomPAY | G3: SEGAMAT | H3: Maker Carry to 29 Sep forecast
A4: 46293 | B4: 46294 | C4: EL GREAT SOLUTION | D4: Upkeep of branch - KLTS | E4: 35 | F4: MBB | G4: KLTS | H4: Maker Carry to 29 Sep forecast
A5: 46294 | B5: 46294 | C5: TGCK | D5: Inventory TGCK 07.09.2026 to 08.09.2026 | E5: 214982.6 | F5: M2E | G5: TGCK | H5: Maker
A6: 46294 | B6: 46294 | C6: AHRA INTERIOR | D6: Outlet renovation - Petaling Jaya (1st payment) | E6: 122330.7 | F6: M2E | G6: PETALING JAYA | H6: Maker
A7: 46294 | B7: 46294 | C7: TK STEEL SUPPLIES | D7: Foodtruck - 6th payment | E7: 20219 | F7: M2E | G7: HQ | H7: Maker
A8: 46294 | B8: 46294 | C8: TENAGA NASIONAL BERHAD | D8: TNB Sep - Sg Besi outlet | E8: 5685 | F8: JomPAY | G8: SG BESI | H8: Maker
A9: 46294 | B9: 46294 | C9: TOP GLOBAL FOOD AND BEVERAGES | D9: Hire purchase RU9577 - Jul 2026 | E9: 4433 | F9: Interbank | G9: HQ | H9: Maker
A10: 46294 | B10: 46294 | C10: IRHAS PUTRA | D10: Rental Oct - S13 G15 training centre | E10: 3900 | F10: MBB | G10: HQ | H10: Maker
A11: 46294 | B11: 46294 | C11: HUSNA | D11: Cash advance - F1 Event | E11: 3845.77 | F11: MBB | G11: HQ | H11: Maker
A12: 46294 | B12: 46294 | C12: TENAGA NASIONAL BERHAD | D12: TNB Sep - BSP 29G outlet | E12: 3540.1 | F12: JomPAY | G12: BSP | H12: Maker
A13: 46294 | B13: 46294 | C13: TENAGA NASIONAL BERHAD | D13: TNB Sep - Cheras 85G outlet | E13: 2754.6 | F13: JomPAY | G13: CHERAS | H13: Maker
... A29: 46294 | B29: 46294 | C29: SYABAS | D29: Syabas Sep - Cheras hostel 3 | E29: 32.45 | F29: JomPAY | G29: CHERAS | H29: Maker
A30: 46295 | B30: 46295 | C30: JABATAN KASTAM DIRAJA MALAYSIA | D30: SST TGFB - Jul & Aug 2026 | E30: 1152543.6 | F30: M2E | G30: TGFB
A31: 46295 | B31: 46295 | C31: TOP GLOBAL FOOD AND BEVERAGES | D31: Hire purchase VHQ537 - Jul 2026 | E31: 5444 | F31: Interbank | G31: HQ | H31: Maker
A32: 46295 | B32: 46295 | C32: NUR HANA NASIHAH | D32: Food training for staff | E32: 5000 | F32: Interbank | G32: HQ
A33: 46295 | B33: 46295 | C33: AINA NOORA | D33: Cash advance - Aina | E33: 2522.66 | F33: Interbank | G33: HQ

Sheet RHB Sep Transactions
A1: Date | B1: Description | C1: Sender / Beneficiary | D1: Reference 1 | E1: Reference 2 | F1: Debit (RM) | G1: Credit (RM) | H1: Balance (RM)
A2: 46266 | B2: CDT CASH DEPOSIT | C2: / | D2: / | E2: / | F2: 0 | G2: 100 | H2: 35980.04
A3: 46266 | B3: CDT CASH DEPOSIT | C3: / | D3: / | E3: / | F3: 0 | G3: 1500 | H3: 37480.04
A4: 46266 | B4: RPP INWARD INST TRF | C4: AMPERA RAYA GLOBAL S / | D4: /KLTS Ampera | E4: /KLTS Gr Sewa Sep26 | F4: 0 | G4: 8600 | H4: 46080.04
A5: 46266 | B5: REFLEX SERVICE TAX D | C5: / | D5: / | E5: M01/ | F5: 4 | G5: 0 | H5: 46076.04
A6: 46266 | B6: REFLEX-SUBSCRIP CHAR | C6: / | D6: / | E6: M01/ | F6: 50 | G6: 0 | H6: 46026.04
A7: 46267 | B7: CDT CASH DEPOSIT | C7: / | D7: / | E7: / | F7: 0 | G7: 1580 | H7: 47606.04
A8: 46268 | B8: CDT CASH DEPOSIT | C8: / | D8: / | E8: / | F8: 0 | G8: 1920 | H8: 49526.04
A9: 46269 | B9: CDT CASH DEPOSIT | C9: / | D9: / | E9: / | F9: 0 | G9: 50 | H9: 49576.04
A10: 46269 | B10: CDT CASH DEPOSIT | C10: / | D10: / | E10: / | F10: 0 | G10: 350 | H10: 49926.04
A11: 46270 | B11: CDT CASH DEPOSIT | C11: / | D11: / | E11: / | F11: 0 | G11: 1180 | H11: 51106.04
A12: 46270 | B12: CDT CASH DEPOSIT | C12: / | D12: / | E12: / | F12: 0 | G12: 1970 | H12: 53076.04
A13: 46271 | B13: CDT CASH DEPOSIT | C13: / | D13: / | E13: / | F13: 0 | G13: 1420 | H13: 54496.04
... A49: 46293 | B49: RFLX INSTANT TRF DR | C49: / AHMAD HANIF ALBAB | D49: 260928013896/salary sept | E49: / | F49: 3600 | G49: 0 | H49: 14440.97
A51: FORECAST 29-30 SEP
A52: 46294 | B52: Forecast cash deposits | F52: 0 | G52: 1775.7143 | H52: =H49+G52-F52
A53: 46295 | B53: Forecast cash deposits | F53: 0 | G53: 1775.7143 | H53: =H52+G53-F53

Sheet Outlet Plan
A1: No. | B1: Project | C1: Grand Opening | D1: Capex Assumption (RM) | E1: Project Cash-Out Date | F1: Daily New Outlet Sales (RM) | G1: Incremental Sales Sep-26 | H1: Incremental Sales Oct-Dec 2026 | I1: Notes
A2: 10 | B2: PASIR GUDANG | C2: 46295 | D2: 650000 | E2: 46265 | F2: 8000 | G2: 8000 | H2: 736000 | I2: First 3 projects: RM650k capex/outlet; project cash-out date falls before Q4
A3: 11 | B3: CHERAS DWITASIK | C3: 46307 | D3: 650000 | E3: 46277 | F3: 8000 | G3: 0 | H3: 648000 | I3: First 3 projects: RM650k capex/outlet; project cash-out date falls before Q4
A4: 12 | B4: PETALING JAYA | C4: 46322 | D4: 650000 | E4: 46292 | F4: 8000 | G4: 0 | H4: 528000 | I4: First 3 projects: RM650k capex/outlet; project cash-out date falls before Q4
A5: 13 | B5: TAIPAN USJ | C5: 46342 | D5: 450000 | E5: 46312 | F5: 8000 | G5: 0 | H5: 368000 | I5: Subsequent projects: RM450k capex/outlet
A6: 14 | B6: BANGSAR | C6: 46344 | D6: 450000 | E6: 46314 | F6: 8000 | G6: 0 | H6: 352000 | I6: Subsequent projects: RM450k capex/outlet
A7: 15 | B7: MACHANG | C7: 46344 | D7: 450000 | E7: 46314 | F7: 8000 | G7: 0 | H7: 352000 | I7: Subsequent projects: RM450k capex/outlet
A8: 16 | B8: ARAU | C8: 46349 | D8: 450000 | E8: 46319 | F8: 8000 | G8: 0 | H8: 312000 | I8: Subsequent projects: RM450k capex/outlet
A9: 17 | B9: PASIR MAS | C9: 46356 | D9: 450000 | E9: 46326 | F9: 8000 | G9: 0 | H9: 256000 | I9: Subsequent projects: RM450k capex/outlet
A10: 18 | B10: KEMAMAN | C10: 46363 | D10: 450000 | E10: 46333 | F10: 8000 | G10: 0 | H10: 200000 | I10: Subsequent projects: RM450k capex/outlet
A11: 19 | B11: CHANGLUN | C11: 46365 | D11: 450000 | E11: 46335 | F11: 8000 | G11: 0 | H11: 184000 | I11: Subsequent projects: RM450k capex/outlet
A12: 20 | B12: MUAR | C12: 46371 | D12: 450000 | E12: 46341 | F12: 8000 | G12: 0 | H12: 136000 | I12: Subsequent projects: RM450k capex/outlet
A13: 21 | B13: ICOMSRWK | C13: TBD | D13: 450000 | E13: TBD | F13: 8000 | G13: 0 | H13: 0 | I13: GO date TBD; excluded until date confirmed
A16: Planning summary
A17: Current outlet count stated as at 30 Sep 2026 | B17: 34
A18: New outlet daily sales assumption | B18: 8000 | C18: RM / day
A19: Sep incremental sales from listed openings | B19: =SUM(G2:G13)
A20: Oct-Dec incremental sales from listed openings | B20: =SUM(H2:H13)

Sheet Q4 Assumptions
A1: TGFB — Q4 2026 Cash Flow Forecast: Assumptions
A2: Blue = input (from you / estimate) · Green = link to another sheet · Black = formula · Yellow = estimate to confirm. Outflows are negative, as in the cash flow template.
A4: GENERAL
A5: Forecast start | B5: 46296 | I5: Day after the Sep-30 bridge
A6: Forecast end | B6: 46387 | I6: Your item 1: up to 31 Dec
A7: Opening Maybank balance (forecast 30 Sep) | B7: ='Sep30 Bridge'!G7 | I7: Sep30 Bridge closing
A8: Opening RHB balance (forecast 30 Sep) | B8: ='Sep30 Bridge'!G12 | I8: Sep30 Bridge closing
A9: Outlets operating at 30 Sep (incl. Pasir Gudang) | B9: 34 | I9: Your item 4
A10: Fixed deposit | B10: Excluded | I10: Your item 11: FD matures 2027 (1-yr tenure) — no FD cash movement in Q4
A12: NEW OUTLETS
A13: Sales per new outlet per day (RM) | B13: 8000 | I13: Your item 2
A14: Rental % of new-outlet sales | B14: 0.05 | I14: Rental part of your original 15% running cost (wages now follow the 2%-per-outlet rule below)
A15: Wage increase per new outlet open | B15: 0.02 | I15: Your instruction: +2% on the payroll (1st-week + 25th) for each new outlet open
A16: Branch Expenditure & Upkeep increase per new outlet open | B16: 0.01 | I16: Your instruction: +1% per new outlet
A17: Inventory purchases increase per new outlet open | B17: 0.03 | I17: Your instruction: +3% per new outlet
A18: Capex paid N days before grand opening | B18: 45 | I18: Your item 6. Lump sum on GO−45; if already past, balance paid 1 Oct
A19: Capex — first 3 outlets (RM/outlet) | B19: 650000 | I19: Your item 5
A20: Capex — subsequent outlets (RM/outlet) | B20: 450000 | I20: Your item 6
A21: Capex paid to 30 Sep — Pasir Gudang | B21: 650000 | I21: ASSUMPTION: Pasir Gudang (opened 30 Sep) fully paid — no further capex in Q4
A22: Capex paid to 30 Sep — Cheras Dwitasik | B22: 91500 | I22: Your item 9
A23: Capex paid to 30 Sep — Petaling Jaya | B23: 122330.7 | I23: Your item 9 (AHRA Interior, 29 Sep)
A24: Deposit per new outlet — 5 outlets Oct–Nov (RM) | B24: 30000 | I24: ASSUMPTION: amount not given (your item 14) — placeholder
A26: WAGES & RHB
A27: RHB cash deposits per day | B27: ='Sep30 Bridge'!D11 | I27: Sep30 Bridge (average daily cash deposit)
A28: Payroll on the 25th (RHB) — base | B28: 475000 | I28: Your instruction: RM450k–500k in the week of the 25th — midpoint RM475k used (Sep RHB payroll was RM439,928)
A29: Minimum RHB balance before Maybank top-up | B29: 20000 | I29: Maybank tops RHB up only when needed for payroll (as on 25 Sep)
A30: Wages — first week of each month (Maybank) — base | B30: 1000000 | I30: Your instruction: RM1M in the first week of the month (paid on the 3rd)
A31: EXISTING 34 OUTLETS — BASELINE FROM SEPTEMBER CASH FLOW STATEMENT (MAYBANK, 1–28 SEP)
A32: Days covered by September actual | B32: 28 | I32: TGFB Cash Flow Sept 2026: 1 Sep opening 14,257,277.95 → 13,269,622.60 (28 Sep actual)
A33: Sep opening balance (Maybank, 1 Sep) | B33: 14257278 | I33: Cash flow statement
A34: Basis: Daily = Sep actual ÷ 28 days, spread every day · Monthly = paid once a month on 'Pay day' · Excluded = one-off, not repeated (Q4 amounts come from the events table below)
A35: Template line | B35: Section | C35: Sep'26 actual | D35: Adjustment | E35: Basis | F35: Pay day | G35: Per day (Q4) | H35: Per month (Q4) | I35: Why
A36: Customers & Sales | B36: Operations — in | C36: 8833557.3 | D36: 0 | E36: Daily | G36: =IF(E36="Daily",(C36+D36)/'Q4 Assumptions'!$B$32,0) | H36: =IF(E36="Monthly",C36+D36,0) | I36: Existing outlets at Sep daily rate. New-outlet sales and RHB cash deposits added on the weekly sheet
A37: Licensing fee | B37: Operations — in | C37: 120000 | D37: 0 | E37: Excluded | G37: =IF(E37="Daily",(C37+D37)/'Q4 Assumptions'!$B$32,0) | H37: =IF(E37="Monthly",C37+D37,0) | I37: One-off licensee fee in Sep — not assumed to recur
A38: Licensing package | B38: Operations — in | C38: 0 | D38: 0 | E38: Excluded | G38: =IF(E38="Daily",(C38+D38)/'Q4 Assumptions'!$B$32,0) | H38: =IF(E38="Monthly",C38+D38,0) | I38: Q4: PJ balance RM255k (events)
A39: Royalty | B39: Operations — in | C39: 296844.55 | D39: 0 | E39: Monthly | F39: 10 | G39: =IF(E39="Daily",(C39+D39)/'Q4 Assumptions'!$B$32,0) | H39: =IF(E39="Monthly",C39+D39,0) | I39: Monthly royalty from licensees
A40: Other operations | B40: Operations — in | C40: 37586.57 | D40: 0 | E40: Daily | G40: =IF(E40="Daily",(C40+D40)/'Q4 Assumptions'!$B$32,0) | H40: =IF(E40="Monthly",C40+D40,0)
A41: Inventory purchases | B41: Operations — out | C41: -4009021.4 | D41: 0 | E41: Daily | G41: =IF(E41="Daily",(C41+D41)/'Q4 Assumptions'!$B$32,0) | H41: =IF(E41="Monthly",C41+D41,0) | I41: Existing outlets at Sep daily rate
A42: Distribution Fee | B42: Operations — out | C42: -187370 | D42: 0 | E42: Daily | G42: =IF(E42="Daily",(C42+D42)/'Q4 Assumptions'!$B$32,0) | H42: =IF(E42="Monthly",C42+D42,0)
A43: Deposit | B43: Operations — out | C43: -227765 | D43: 0 | E43: Excluded | G43: =IF(E43="Daily",(C43+D43)/'Q4 Assumptions'!$B$32,0) | H43: =IF(E43="Monthly",C43+D43,0) | I43: Sep deposits one-off. Q4: 5 new-outlet deposits (events)
...

Sheet Q4 Weekly Cash Flow
A1: TOP GLOBAL FOOD AND BEVERAGES SDN BHD
A2: Q4 2026 WEEKLY CASH FLOW FORECAST — MAYBANK + RHB COMBINED
B4: Period Beginning | C4: ='Q4 Assumptions'!$B$5
B5: Period Ending | C5: ='Q4 Assumptions'!$B$6
B6: Cash at Beginning of Period | C6: =R76
B7: Cash at End of Period | C7: =R77
A9: Operations | C9: Sept'26 Actual | D9: Week 1 | E9: Week 2 | F9: Week 3 | G9: Week 4 | H9: Week 5 | I9: Week 6 | J9: Week 7 | K9: Week 8 | L9: Week 9 | M9: Week 10 | N9: Week 11 | O9: Week 12 | P9: Week 13 | Q9: Week 14 | R9: Q4 Total
B10: Week start | C10: 1-Sep-26 to | D10: ='Q4 Assumptions'!$B$5 | E10: =D11+1 | F10: =E11+1 | G10: =F11+1 | H10: =G11+1 | I10: =H11+1 | J10: =I11+1 | K10: =J11+1 | L10: =K11+1 | ... Q10: =P11+1
B11: Week end | C11: 28-Sep-26 | D11: =MIN(D10+6-MOD(D10-2,7),'Q4 Assumptions'!$B$6) | E11: =MIN(E10+6-MOD(E10-2,7),'Q4 Assumptions'!$B$6) | F11: =MIN(F10+6-MOD(F10-2,7),'Q4 Assumptions'!$B$6) | G11: =MIN(G10+6-MOD(G10-2,7),'Q4 Assumptions'!$B$6) | H11: =MIN(H10+6-MOD(H10-2,7),'Q4 Assumptions'!$B$6) | I11: =MIN(I10+6-MOD(I10-2,7),'Q4 Assumptions'!$B$6) | J11: =MIN(J10+6-MOD(J10-2,7),'Q4 Assumptions'!$B$6) | K11: =MIN(K10+6-MOD(K10-2,7),'Q4 Assumptions'!$B$6) | ... Q11: =MIN(Q10+6-MOD(Q10-2,7),'Q4 Assumptions'!$B$6)
B12: Days | C12: Maybank only | D12: =D11-D10+1 | E12: =E11-E10+1 | F12: =F11-F10+1 | G12: =G11-G10+1 | H12: =H11-H10+1 | I12: =I11-I10+1 | J12: =J11-J10+1 | K12: =K11-K10+1 | ... Q12: =Q11-Q10+1 | R12: =SUM(D12:Q12)
A13: Cash receipts from
B14: Customers & Sales | C14: ='Q4 Assumptions'!C36 | D14: ='Q4 Assumptions'!$G$36*D$12+SUMIFS('Q4 Assumptions'!$C$85:$C$133,'Q4 Assumptions'!$D$85:$D$133,'Q4 Assumptions'!$A$36,'Q4 Assumptions'!$B$85:$B$133,">="&D$10,'Q4 Assumptions'!$B$85:$B$133,"<="&D$11)+D83+D90 | E14: ='Q4 Assumptions'!$G$36*E$12+SUMIFS('Q4 Assumptions'!$C$85:$C$133,'Q4 Assumptions'!$D$85:$D$133,'Q4 Assumptions'!$A$36,'Q4 Assumptions'!$B$85:$B$133,">="&E$10,'Q4 Assumptions'!$B$85:$B$133,"<="&E$11)+E83+E90 | F14: ='Q4 Assumptions'!$G$36*F$12+SUMIFS('Q4 Assumptions'!$C$85:$C$133,'Q4 Assumptions'!$D$85:$D$133,'Q4 Assumptions'!$A$36,'Q4 Assumptions'!$B$85:$B$133,">="&F$10,'Q4 Assumptions'!$B$85:$B$133,"<="&F$11)+F83+F90 | G14: ='Q4 Assumptions'!$G$36*G$12+SUMIFS('Q4 Assumptions'!$C$85:$C$133,'Q4 Assumptions'!$D$85:$D$133,'Q4 Assumptions'!$A$36,'Q4 Assumptions'!$B$85:$B$133,">="&G$10,'Q4 Assumptions'!$B$85:$B$133,"<="&G$11)+G83+G90 | H14: ='Q4 Assumptions'!$G$36*H$12+SUMIFS('Q4 Assumptions'!$C$85:$C$133,'Q4 Assumptions'!$D$85:$D$133,'Q4 Assumptions'!$A$36,'Q4 Assumptions'!$B$85:$B$133,">="&H$10,'Q4 Assumptions'!$B$85:$B$133,"<="&H$11)+H83+H90 | I14: ='Q4 Assumptions'!$G$36*I$12+SUMIFS('Q4 Assumptions'!$C$85:$C$133,'Q4 Assumptions'!$D$85:$D$133,'Q4 Assumptions'!$A$36,'Q4 Assumptions'!$B$85:$B$133,">="&I$10,'Q4 Assumptions'!$B$85:$B$133,"<="&I$11)+I83+I90 | J14: ='Q4 Assumptions'!$G$36*J$12+SUMIFS('Q4 Assumptions'!$C$85:$C$133,'Q4 Assumptions'!$D$85:$D$133,'Q4 Assumptions'!$A$36,'Q4 Assumptions'!$B$85:$B$133,">="&J$10,'Q4 Assumptions'!$B$85:$B$133,"<="&J$11)+J83+J90 | K14: ='Q4 Assumptions'!$G$36*K$12+SUMIFS('Q4 Assumptions'!$C$85:$C$133,'Q4 Assumptions'!$D$85:$D$133,'Q4 Assumptions'!$A$36,'Q4 Assumptions'!$B$85:$B$133,">="&K$10,'Q4 Assumptions'!$B$85:$B$133,"<="&K$11)+K83+K90 | ... Q14: ='Q4 Assumptions'!$G$36*Q$12+SUMIFS('Q4 Assumptions'!$C$85:$C$133,'Q4 Assumptions'!$D$85:$D$133,'Q4 Assumptions'!$A$36,'Q4 Assumptions'!$B$85:$B$133,">="&Q$10,'Q4 Assumptions'!$B$85:$B$133,"<="&Q$11)+Q83+Q90 | R14: =SUM(D14:Q14)
B15: Licensing fee | C15: ='Q4 Assumptions'!C37 | D15: ='Q4 Assumptions'!$G$37*D$12+SUMIFS('Q4 Assumptions'!$C$85:$C$133,'Q4 Assumptions'!$D$85:$D$133,'Q4 Assumptions'!$A$37,'Q4 Assumptions'!$B$85:$B$133,">="&D$10,'Q4 Assumptions'!$B$85:$B$133,"<="&D$11) | E15: ='Q4 Assumptions'!$G$37*E$12+SUMIFS('Q4 Assumptions'!$C$85:$C$133,'Q4 Assumptions'!$D$85:$D$133,'Q4 Assumptions'!$A$37,'Q4 Assumptions'!$B$85:$B$133,">="&E$10,'Q4 Assumptions'!$B$85:$B$133,"<="&E$11) | F15: ='Q4 Assumptions'!$G$37*F$12+SUMIFS('Q4 Assumptions'!$C$85:$C$133,'Q4 Assumptions'!$D$85:$D$133,'Q4 Assumptions'!$A$37,'Q4 Assumptions'!$B$85:$B$133,">="&F$10,'Q4 Assumptions'!$B$85:$B$133,"<="&F$11) | G15: ='Q4 Assumptions'!$G$37*G$12+SUMIFS('Q4 Assumptions'!$C$85:$C$133,'Q4 Assumptions'!$D$85:$D$133,'Q4 Assumptions'!$A$37,'Q4 Assumptions'!$B$85:$B$133,">="&G$10,'Q4 Assumptions'!$B$85:$B$133,"<="&G$11) | H15: ='Q4 Assumptions'!$G$37*H$12+SUMIFS('Q4 Assumptions'!$C$85:$C$133,'Q4 Assumptions'!$D$85:$D$133,'Q4 Assumptions'!$A$37,'Q4 Assumptions'!$B$85:$B$133,">="&H$10,'Q4 Assumptions'!$B$85:$B$133,"<="&H$11) | I15: ='Q4 Assumptions'!$G$37*I$12+SUMIFS('Q4 Assumptions'!$C$85:$C$133,'Q4 Assumptions'!$D$85:$D$133,'Q4 Assumptions'!$A$37,'Q4 Assumptions'!$B$85:$B$133,">="&I$10,'Q4 Assumptions'!$B$85:$B$133,"<="&I$11) | J15: ='Q4 Assumptions'!$G$37*J$12+SUMIFS('Q4 Assumptions'!$C$85:$C$133,'Q4 Assumptions'!$D$85:$D$133,'Q4 Assumptions'!$A$37,'Q4 Assumptions'!$B$85:$B$133,">="&J$10,'Q4 Assumptions'!$B$85:$B$133,"<="&J$11) | K15: ='Q4 Assumptions'!$G$37*K$12+SUMIFS('Q4 Assumptions'!$C$85:$C$133,'Q4 Assumptions'!$D$85:$D$133,'Q4 Assumptions'!$A$37,'Q4 Assumptions'!$B$85:$B$133,">="&K$10,'Q4 Assumptions'!$B$85:$B$133,"<="&K$11) | ... Q15: ='Q4 Assumptions'!$G$37*Q$12+SUMIFS('Q4 Assumptions'!$C$85:$C$133,'Q4 Assumptions'!$D$85:$D$133,'Q4 Assumptions'!$A$37,'Q4 Assumptions'!$B$85:$B$133,">="&Q$10,'Q4 Assumptions'!$B$85:$B$133,"<="&Q$11) | R15: =SUM(D15:Q15)
B16: Licensing package | C16: ='Q4 Assumptions'!C38 | D16: ='Q4 Assumptions'!$G$38*D$12+SUMIFS('Q4 Assumptions'!$C$85:$C$133,'Q4 Assumptions'!$D$85:$D$133,'Q4 Assumptions'!$A$38,'Q4 Assumptions'!$B$85:$B$133,">="&D$10,'Q4 Assumptions'!$B$85:$B$133,"<="&D$11) | E16: ='Q4 Assumptions'!$G$38*E$12+SUMIFS('Q4 Assumptions'!$C$85:$C$133,'Q4 Assumptions'!$D$85:$D$133,'Q4 Assumptions'!$A$38,'Q4 Assumptions'!$B$85:$B$133,">="&E$10,'Q4 Assumptions'!$B$85:$B$133,"<="&E$11) | F16: ='Q4 Assumptions'!$G$38*F$12+SUMIFS('Q4 Assumptions'!$C$85:$C$133,'Q4 Assumptions'!$D$85:$D$133,'Q4 Assumptions'!$A$38,'Q4 Assumptions'!$B$85:$B$133,">="&F$10,'Q4 Assumptions'!$B$85:$B$133,"<="&F$11) | G16: ='Q4 Assumptions'!$G$38*G$12+SUMIFS('Q4 Assumptions'!$C$85:$C$133,'Q4 Assumptions'!$D$85:$D$133,'Q4 Assumptions'!$A$38,'Q4 Assumptions'!$B$85:$B$133,">="&G$10,'Q4 Assumptions'!$B$85:$B$133,"<="&G$11) | H16: ='Q4 Assumptions'!$G$38*H$12+SUMIFS('Q4 Assumptions'!$C$85:$C$133,'Q4 Assumptions'!$D$85:$D$133,'Q4 Assumptions'!$A$38,'Q4 Assumptions'!$B$85:$B$133,">="&H$10,'Q4 Assumptions'!$B$85:$B$133,"<="&H$11) | I16: ='Q4 Assumptions'!$G$38*I$12+SUMIFS('Q4 Assumptions'!$C$85:$C$133,'Q4 Assumptions'!$D$85:$D$133,'Q4 Assumptions'!$A$38,'Q4 Assumptions'!$B$85:$B$133,">="&I$10,'Q4 Assumptions'!$B$85:$B$133,"<="&I$11) | J16: ='Q4 Assumptions'!$G$38*J$12+SUMIFS('Q4 Assumptions'!$C$85:$C$133,'Q4 Assumptions'!$D$85:$D$133,'Q4 Assumptions'!$A$38,'Q4 Assumptions'!$B$85:$B$133,">="&J$10,'Q4 Assumptions'!$B$85:$B$133,"<="&J$11) | K16: ='Q4 Assumptions'!$G$38*K$12+SUMIFS('Q4 Assumptions'!$C$85:$C$133,'Q4 Assumptions'!$D$85:$D$133,'Q4 Assumptions'!$A$38,'Q4 Assumptions'!$B$85:$B$133,">="&K$10,'Q4 Assumptions'!$B$85:$B$133,"<="&K$11) | ... Q16: ='Q4 Assumptions'!$G$38*Q$12+SUMIFS('Q4 Assumptions'!$C$85:$C$133,'Q4 Assumptions'!$D$85:$D$133,'Q4 Assumptions'!$A$38,'Q4 Assumptions'!$B$85:$B$133,">="&Q$10,'Q4 Assumptions'!$B$85:$B$133,"<="&Q$11) | R16: =SUM(D16:Q16)
B17: Royalty | C17: ='Q4 Assumptions'!C39 | D17: ='Q4 Assumptions'!$G$39*D$12+SUMIFS('Q4 Assumptions'!$C$85:$C$133,'Q4 Assumptions'!$D$85:$D$133,'Q4 Assumptions'!$A$39,'Q4 Assumptions'!$B$85:$B$133,">="&D$10,'Q4 Assumptions'!$B$85:$B$133,"<="&D$11) | E17: ='Q4 Assumptions'!$G$39*E$12+SUMIFS('Q4 Assumptions'!$C$85:$C$133,'Q4 Assumptions'!$D$85:$D$133,'Q4 Assumptions'!$A$39,'Q4 Assumptions'!$B$85:$B$133,">="&E$10,'Q4 Assumptions'!$B$85:$B$133,"<="&E$11) | F17: ='Q4 Assumptions'!$G$39*F$12+SUMIFS('Q4 Assumptions'!$C$85:$C$133,'Q4 Assumptions'!$D$85:$D$133,'Q4 Assumptions'!$A$39,'Q4 Assumptions'!$B$85:$B$133,">="&F$10,'Q4 Assumptions'!$B$85:$B$133,"<="&F$11) | G17: ='Q4 Assumptions'!$G$39*G$12+SUMIFS('Q4 Assumptions'!$C$85:$C$133,'Q4 Assumptions'!$D$85:$D$133,'Q4 Assumptions'!$A$39,'Q4 Assumptions'!$B$85:$B$133,">="&G$10,'Q4 Assumptions'!$B$85:$B$133,"<="&G$11) | H17: ='Q4 Assumptions'!$G$39*H$12+SUMIFS('Q4 Assumptions'!$C$85:$C$133,'Q4 Assumptions'!$D$85:$D$133,'Q4 Assumptions'!$A$39,'Q4 Assumptions'!$B$85:$B$133,">="&H$10,'Q4 Assumptions'!$B$85:$B$133,"<="&H$11) | I17: ='Q4 Assumptions'!$G$39*I$12+SUMIFS('Q4 Assumptions'!$C$85:$C$133,'Q4 Assumptions'!$D$85:$D$133,'Q4 Assumptions'!$A$39,'Q4 Assumptions'!$B$85:$B$133,">="&I$10,'Q4 Assumptions'!$B$85:$B$133,"<="&I$11) | J17: ='Q4 Assumptions'!$G$39*J$12+SUMIFS('Q4 Assumptions'!$C$85:$C$133,'Q4 Assumptions'!$D$85:$D$133,'Q4 Assumptions'!$A$39,'Q4 Assumptions'!$B$85:$B$133,">="&J$10,'Q4 Assumptions'!$B$85:$B$133,"<="&J$11) | K17: ='Q4 Assumptions'!$G$39*K$12+SUMIFS('Q4 Assumptions'!$C$85:$C$133,'Q4 Assumptions'!$D$85:$D$133,'Q4 Assumptions'!$A$39,'Q4 Assumptions'!$B$85:$B$133,">="&K$10,'Q4 Assumptions'!$B$85:$B$133,"<="&K$11) | ... Q17: ='Q4 Assumptions'!$G$39*Q$12+SUMIFS('Q4 Assumptions'!$C$85:$C$133,'Q4 Assumptions'!$D$85:$D$133,'Q4 Assumptions'!$A$39,'Q4 Assumptions'!$B$85:$B$133,">="&Q$10,'Q4 Assumptions'!$B$85:$B$133,"<="&Q$11) | R17: =SUM(D17:Q17)
B18: Other operations | C18: ='Q4 Assumptions'!C40 | D18: ='Q4 Assumptions'!$G$40*D$12+SUMIFS('Q4 Assumptions'!$C$85:$C$133,'Q4 Assumptions'!$D$85:$D$133,'Q4 Assumptions'!$A$40,'Q4 Assumptions'!$B$85:$B$133,">="&D$10,'Q4 Assumptions'!$B$85:$B$133,"<="&D$11) | E18: ='Q4 Assumptions'!$G$40*E$12+SUMIFS('Q4 Assumptions'!$C$85:$C$133,'Q4 Assumptions'!$D$85:$D$133,'Q4 Assumptions'!$A$40,'Q4 Assumptions'!$B$85:$B$133,">="&E$10,'Q4 Assumptions'!$B$85:$B$133,"<="&E$11) | F18: ='Q4 Assumptions'!$G$40*F$12+SUMIFS('Q4 Assumptions'!$C$85:$C$133,'Q4 Assumptions'!$D$85:$D$133,'Q4 Assumptions'!$A$40,'Q4 Assumptions'!$B$85:$B$133,">="&F$10,'Q4 Assumptions'!$B$85:$B$133,"<="&F$11) | G18: ='Q4 Assumptions'!$G$40*G$12+SUMIFS('Q4 Assumptions'!$C$85:$C$133,'Q4 Assumptions'!$D$85:$D$133,'Q4 Assumptions'!$A$40,'Q4 Assumptions'!$B$85:$B$133,">="&G$10,'Q4 Assumptions'!$B$85:$B$133,"<="&G$11) | H18: ='Q4 Assumptions'!$G$40*H$12+SUMIFS('Q4 Assumptions'!$C$85:$C$133,'Q4 Assumptions'!$D$85:$D$133,'Q4 Assumptions'!$A$40,'Q4 Assumptions'!$B$85:$B$133,">="&H$10,'Q4 Assumptions'!$B$85:$B$133,"<="&H$11) | I18: ='Q4 Assumptions'!$G$40*I$12+SUMIFS('Q4 Assumptions'!$C$85:$C$133,'Q4 Assumptions'!$D$85:$D$133,'Q4 Assumptions'!$A$40,'Q4 Assumptions'!$B$85:$B$133,">="&I$10,'Q4 Assumptions'!$B$85:$B$133,"<="&I$11) | J18: ='Q4 Assumptions'!$G$40*J$12+SUMIFS('Q4 Assumptions'!$C$85:$C$133,'Q4 Assumptions'!$D$85:$D$133,'Q4 Assumptions'!$A$40,'Q4 Assumptions'!$B$85:$B$133,">="&J$10,'Q4 Assumptions'!$B$85:$B$133,"<="&J$11) | K18: ='Q4 Assumptions'!$G$40*K$12+SUMIFS('Q4 Assumptions'!$C$85:$C$133,'Q4 Assumptions'!$D$85:$D$133,'Q4 Assumptions'!$A$40,'Q4 Assumptions'!$B$85:$B$133,">="&K$10,'Q4 Assumptions'!$B$85:$B$133,"<="&K$11) | ... Q18: ='Q4 Assumptions'!$G$40*Q$12+SUMIFS('Q4 Assumptions'!$C$85:$C$133,'Q4 Assumptions'!$D$85:$D$133,'Q4 Assumptions'!$A$40,'Q4 Assumptions'!$B$85:$B$133,">="&Q$10,'Q4 Assumptions'!$B$85:$B$133,"<="&Q$11) | R18: =SUM(D18:Q18)
C19: =SUM(C14:C18) | D19: =SUM(D14:D18) | E19: =SUM(E14:E18) | F19: =SUM(F14:F18) | G19: =SUM(G14:G18) | H19: =SUM(H14:H18) | I19: =SUM(I14:I18) | J19: =SUM(J14:J18) | ... R19: =SUM(R14:R18)
A20: Cash paid for
B21: Inventory purchases | C21: ='Q4 Assumptions'!C41 | D21: ='Q4 Assumptions'!$G$41*D$12+SUMIFS('Q4 Assumptions'!$C$85:$C$133,'Q4 Assumptions'!$D$85:$D$133,'Q4 Assumptions'!$A$41,'Q4 Assumptions'!$B$85:$B$133,">="&D$10,'Q4 Assumptions'!$B$85:$B$133,"<="&D$11)+D87 | E21: ='Q4 Assumptions'!$G$41*E$12+SUMIFS('Q4 Assumptions'!$C$85:$C$133,'Q4 Assumptions'!$D$85:$D$133,'Q4 Assumptions'!$A$41,'Q4 Assumptions'!$B$85:$B$133,">="&E$10,'Q4 Assumptions'!$B$85:$B$133,"<="&E$11)+E87 | F21: ='Q4 Assumptions'!$G$41*F$12+SUMIFS('Q4 Assumptions'!$C$85:$C$133,'Q4 Assumptions'!$D$85:$D$133,'Q4 Assumptions'!$A$41,'Q4 Assumptions'!$B$85:$B$133,">="&F$10,'Q4 Assumptions'!$B$85:$B$133,"<="&F$11)+F87 | G21: ='Q4 Assumptions'!$G$41*G$12+SUMIFS('Q4 Assumptions'!$C$85:$C$133,'Q4 Assumptions'!$D$85:$D$133,'Q4 Assumptions'!$A$41,'Q4 Assumptions'!$B$85:$B$133,">="&G$10,'Q4 Assumptions'!$B$85:$B$133,"<="&G$11)+G87 | H21: ='Q4 Assumptions'!$G$41*H$12+SUMIFS('Q4 Assumptions'!$C$85:$C$133,'Q4 Assumptions'!$D$85:$D$133,'Q4 Assumptions'!$A$41,'Q4 Assumptions'!$B$85:$B$133,">="&H$10,'Q4 Assumptions'!$B$85:$B$133,"<="&H$11)+H87 | I21: ='Q4 Assumptions'!$G$41*I$12+SUMIFS('Q4 Assumptions'!$C$85:$C$133,'Q4 Assumptions'!$D$85:$D$133,'Q4 Assumptions'!$A$41,'Q4 Assumptions'!$B$85:$B$133,">="&I$10,'Q4 Assumptions'!$B$85:$B$133,"<="&I$11)+I87 | J21: ='Q4 Assumptions'!$G$41*J$12+SUMIFS('Q4 Assumptions'!$C$85:$C$133,'Q4 Assumptions'!$D$85:$D$133,'Q4 Assumptions'!$A$41,'Q4 Assumptions'!$B$85:$B$133,">="&J$10,'Q4 Assumptions'!$B$85:$B$133,"<="&J$11)+J87 | K21: ='Q4 Assumptions'!$G$41*K$12+SUMIFS('Q4 Assumptions'!$C$85:$C$133,'Q4 Assumptions'!$D$85:$D$133,'Q4 Assumptions'!$A$41,'Q4 Assumptions'!$B$85:$B$133,">="&K$10,'Q4 Assumptions'!$B$85:$B$133,"<="&K$11)+K87 | ... Q21: ='Q4 Assumptions'!$G$41*Q$12+SUMIFS('Q4 Assumptions'!$C$85:$C$133,'Q4 Assumptions'!$D$85:$D$133,'Q4 Assumptions'!$A$41,'Q4 Assumptions'!$B$85:$B$133,">="&Q$10,'Q4 Assumptions'!$B$85:$B$133,"<="&Q$11)+Q87 | R21: =SUM(D21:Q21)
B22: Distribution Fee | C22: ='Q4 Assumptions'!C42 | D22: ='Q4 Assumptions'!$G$42*D$12+SUMIFS('Q4 Assumptions'!$C$85:$C$133,'Q4 Assumptions'!$D$85:$D$133,'Q4 Assumptions'!$A$42,'Q4 Assumptions'!$B$85:$B$133,">="&D$10,'Q4 Assumptions'!$B$85:$B$133,"<="&D$11) | E22: ='Q4 Assumptions'!$G$42*E$12+SUMIFS('Q4 Assumptions'!$C$85:$C$133,'Q4 Assumptions'!$D$85:$D$133,'Q4 Assumptions'!$A$42,'Q4 Assumptions'!$B$85:$B$133,">="&E$10,'Q4 Assumptions'!$B$85:$B$133,"<="&E$11) | F22: ='Q4 Assumptions'!$G$42*F$12+SUMIFS('Q4 Assumptions'!$C$85:$C$133,'Q4 Assumptions'!$D$85:$D$133,'Q4 Assumptions'!$A$42,'Q4 Assumptions'!$B$85:$B$133,">="&F$10,'Q4 Assumptions'!$B$85:$B$133,"<="&F$11) | G22: ='Q4 Assumptions'!$G$42*G$12+SUMIFS('Q4 Assumptions'!$C$85:$C$133,'Q4 Assumptions'!$D$85:$D$133,'Q4 Assumptions'!$A$42,'Q4 Assumptions'!$B$85:$B$133,">="&G$10,'Q4 Assumptions'!$B$85:$B$133,"<="&G$11) | H22: ='Q4 Assumptions'!$G$42*H$12+SUMIFS('Q4 Assumptions'!$C$85:$C$133,'Q4 Assumptions'!$D$85:$D$133,'Q4 Assumptions'!$A$42,'Q4 Assumptions'!$B$85:$B$133,">="&H$10,'Q4 Assumptions'!$B$85:$B$133,"<="&H$11) | I22: ='Q4 Assumptions'!$G$42*I$12+SUMIFS('Q4 Assumptions'!$C$85:$C$133,'Q4 Assumptions'!$D$85:$D$133,'Q4 Assumptions'!$A$42,'Q4 Assumptions'!$B$85:$B$133,">="&I$10,'Q4 Assumptions'!$B$85:$B$133,"<="&I$11) | J22: ='Q4 Assumptions'!$G$42*J$12+SUMIFS('Q4 Assumptions'!$C$85:$C$133,'Q4 Assumptions'!$D$85:$D$133,'Q4 Assumptions'!$A$42,'Q4 Assumptions'!$B$85:$B$133,">="&J$10,'Q4 Assumptions'!$B$85:$B$133,"<="&J$11) | K22: ='Q4 Assumptions'!$G$42*K$12+SUMIFS('Q4 Assumptions'!$C$85:$C$133,'Q4 Assumptions'!$D$85:$D$133,'Q4 Assumptions'!$A$42,'Q4 Assumptions'!$B$85:$B$133,">="&K$10,'Q4 Assumptions'!$B$85:$B$133,"<="&K$11) | ... Q22: ='Q4 Assumptions'!$G$42*Q$12+SUMIFS('Q4 Assumptions'!$C$85:$C$133,'Q4 Assumptions'!$D$85:$D$133,'Q4 Assumptions'!$A$42,'Q4 Assumptions'!$B$85:$B$133,">="&Q$10,'Q4 Assumptions'!$B$85:$B$133,"<="&Q$11) | R22: =SUM(D22:Q22)
B23: Deposit | C23: ='Q4 Assumptions'!C43 | D23: ='Q4 Assumptions'!$G$43*D$12+SUMIFS('Q4 Assumptions'!$C$85:$C$133,'Q4 Assumptions'!$D$85:$D$133,'Q4 Assumptions'!$A$43,'Q4 Assumptions'!$B$85:$B$133,">="&D$10,'Q4 Assumptions'!$B$85:$B$133,"<="&D$11) | E23: ='Q4 Assumptions'!$G$43*E$12+SUMIFS('Q4 Assumptions'!$C$85:$C$133,'Q4 Assumptions'!$D$85:$D$133,'Q4 Assumptions'!$A$43,'Q4 Assumptions'!$B$85:$B$133,">="&E$10,'Q4 Assumptions'!$B$85:$B$133,"<="&E$11) | F23: ='Q4 Assumptions'!$G$43*F$12+SUMIFS('Q4 Assumptions'!$C$85:$C$133,'Q4 Assumptions'!$D$85:$D$133,'Q4 Assumptions'!$A$43,'Q4 Assumptions'!$B$85:$B$133,">="&F$10,'Q4 Assumptions'!$B$85:$B$133,"<="&F$11) | G23: ='Q4 Assumptions'!$G$43*G$12+SUMIFS('Q4 Assumptions'!$C$85:$C$133,'Q4 Assumptions'!$D$85:$D$133,'Q4 Assumptions'!$A$43,'Q4 Assumptions'!$B$85:$B$133,">="&G$10,'Q4 Assumptions'!$B$85:$B$133,"<="&G$11) | H23: ='Q4 Assumptions'!$G$43*H$12+SUMIFS('Q4 Assumptions'!$C$85:$C$133,'Q4 Assumptions'!$D$85:$D$133,'Q4 Assumptions'!$A$43,'Q4 Assumptions'!$B$85:$B$133,">="&H$10,'Q4 Assumptions'!$B$85:$B$133,"<="&H$11) | I23: ='Q4 Assumptions'!$G$43*I$12+SUMIFS('Q4 Assumptions'!$C$85:$C$133,'Q4 Assumptions'!$D$85:$D$133,'Q4 Assumptions'!$A$43,'Q4 Assumptions'!$B$85:$B$133,">="&I$10,'Q4 Assumptions'!$B$85:$B$133,"<="&I$11) | J23: ='Q4 Assumptions'!$G$43*J$12+SUMIFS('Q4 Assumptions'!$C$85:$C$133,'Q4 Assumptions'!$D$85:$D$133,'Q4 Assumptions'!$A$43,'Q4 Assumptions'!$B$85:$B$133,">="&J$10,'Q4 Assumptions'!$B$85:$B$133,"<="&J$11) | K23: ='Q4 Assumptions'!$G$43*K$12+SUMIFS('Q4 Assumptions'!$C$85:$C$133,'Q4 Assumptions'!$D$85:$D$133,'Q4 Assumptions'!$A$43,'Q4 Assumptions'!$B$85:$B$133,">="&K$10,'Q4 Assumptions'!$B$85:$B$133,"<="&K$11) | ... Q23: ='Q4 Assumptions'!$G$43*Q$12+SUMIFS('Q4 Assumptions'!$C$85:$C$133,'Q4 Assumptions'!$D$85:$D$133,'Q4 Assumptions'!$A$43,'Q4 Assumptions'!$B$85:$B$133,">="&Q$10,'Q4 Assumptions'!$B$85:$B$133,"<="&Q$11) | R23: =SUM(D23:Q23)
B24: HQ Operation | C24: ='Q4 Assumptions'!C44 | D24: ='Q4 Assumptions'!$G$44*D$12+SUMIFS('Q4 Assumptions'!$C$85:$C$133,'Q4 Assumptions'!$D$85:$D$133,'Q4 Assumptions'!$A$44,'Q4 Assumptions'!$B$85:$B$133,">="&D$10,'Q4 Assumptions'!$B$85:$B$133,"<="&D$11) | E24: ='Q4 Assumptions'!$G$44*E$12+SUMIFS('Q4 Assumptions'!$C$85:$C$133,'Q4 Assumptions'!$D$85:$D$133,'Q4 Assumptions'!$A$44,'Q4 Assumptions'!$B$85:$B$133,">="&E$10,'Q4 Assumptions'!$B$85:$B$133,"<="&E$11) | F24: ='Q4 Assumptions'!$G$44*F$12+SUMIFS('Q4 Assumptions'!$C$85:$C$133,'Q4 Assumptions'!$D$85:$D$133,'Q4 Assumptions'!$A$44,'Q4 Assumptions'!$B$85:$B$133,">="&F$10,'Q4 Assumptions'!$B$85:$B$133,"<="&F$11) | G24: ='Q4 Assumptions'!$G$44*G$12+SUMIFS('Q4 Assumptions'!$C$85:$C$133,'Q4 Assumptions'!$D$85:$D$133,'Q4 Assumptions'!$A$44,'Q4 Assumptions'!$B$85:$B$133,">="&G$10,'Q4 Assumptions'!$B$85:$B$133,"<="&G$11) | H24: ='Q4 Assumptions'!$G$44*H$12+SUMIFS('Q4 Assumptions'!$C$85:$C$133,'Q4 Assumptions'!$D$85:$D$133,'Q4 Assumptions'!$A$44,'Q4 Assumptions'!$B$85:$B$133,">="&H$10,'Q4 Assumptions'!$B$85:$B$133,"<="&H$11) | I24: ='Q4 Assumptions'!$G$44*I$12+SUMIFS('Q4 Assumptions'!$C$85:$C$133,'Q4 Assumptions'!$D$85:$D$133,'Q4 Assumptions'!$A$44,'Q4 Assumptions'!$B$85:$B$133,">="&I$10,'Q4 Assumptions'!$B$85:$B$133,"<="&I$11) | J24: ='Q4 Assumptions'!$G$44*J$12+SUMIFS('Q4 Assumptions'!$C$85:$C$133,'Q4 Assumptions'!$D$85:$D$133,'Q4 Assumptions'!$A$44,'Q4 Assumptions'!$B$85:$B$133,">="&J$10,'Q4 Assumptions'!$B$85:$B$133,"<="&J$11) | K24: ='Q4 Assumptions'!$G$44*K$12+SUMIFS('Q4 Assumptions'!$C$85:$C$133,'Q4 Assumptions'!$D$85:$D$133,'Q4 Assumptions'!$A$44,'Q4 Assumptions'!$B$85:$B$133,">="&K$10,'Q4 Assumptions'!$B$85:$B$133,"<="&K$11) | ... Q24: ='Q4 Assumptions'!$G$44*Q$12+SUMIFS('Q4 Assumptions'!$C$85:$C$133,'Q4 Assumptions'!$D$85:$D$133,'Q4 Assumptions'!$A$44,'Q4 Assumptions'!$B$85:$B$133,">="&Q$10,'Q4 Assumptions'!$B$85:$B$133,"<="&Q$11) | R24: =SUM(D24:Q24)
B25: Operation | C25: ='Q4 Assumptions'!C45 | D25: ='Q4 Assumptions'!$G$45*D$12+SUMIFS('Q4 Assumptions'!$C$85:$C$133,'Q4 Assumptions'!$D$85:$D$133,'Q4 Assumptions'!$A$45,'Q4 Assumptions'!$B$85:$B$133,">="&D$10,'Q4 Assumptions'!$B$85:$B$133,"<="&D$11) | E25: ='Q4 Assumptions'!$G$45*E$12+SUMIFS('Q4 Assumptions'!$C$85:$C$133,'Q4 Assumptions'!$D$85:$D$133,'Q4 Assumptions'!$A$45,'Q4 Assumptions'!$B$85:$B$133,">="&E$10,'Q4 Assumptions'!$B$85:$B$133,"<="&E$11) | F25: ='Q4 Assumptions'!$G$45*F$12+SUMIFS('Q4 Assumptions'!$C$85:$C$133,'Q4 Assumptions'!$D$85:$D$133,'Q4 Assumptions'!$A$45,'Q4 Assumptions'!$B$85:$B$133,">="&F$10,'Q4 Assumptions'!$B$85:$B$133,"<="&F$11) | G25: ='Q4 Assumptions'!$G$45*G$12+SUMIFS('Q4 Assumptions'!$C$85:$C$133,'Q4 Assumptions'!$D$85:$D$133,'Q4 Assumptions'!$A$45,'Q4 Assumptions'!$B$85:$B$133,">="&G$10,'Q4 Assumptions'!$B$85:$B$133,"<="&G$11) | H25: ='Q4 Assumptions'!$G$45*H$12+SUMIFS('Q4 Assumptions'!$C$85:$C$133,'Q4 Assumptions'!$D$85:$D$133,'Q4 Assumptions'!$A$45,'Q4 Assumptions'!$B$85:$B$133,">="&H$10,'Q4 Assumptions'!$B$85:$B$133,"<="&H$11) | I25: ='Q4 Assumptions'!$G$45*I$12+SUMIFS('Q4 Assumptions'!$C$85:$C$133,'Q4 Assumptions'!$D$85:$D$133,'Q4 Assumptions'!$A$45,'Q4 Assumptions'!$B$85:$B$133,">="&I$10,'Q4 Assumptions'!$B$85:$B$133,"<="&I$11) | J25: ='Q4 Assumptions'!$G$45*J$12+SUMIFS('Q4 Assumptions'!$C$85:$C$133,'Q4 Assumptions'!$D$85:$D$133,'Q4 Assumptions'!$A$45,'Q4 Assumptions'!$B$85:$B$133,">="&J$10,'Q4 Assumptions'!$B$85:$B$133,"<="&J$11) | K25: ='Q4 Assumptions'!$G$45*K$12+SUMIFS('Q4 Assumptions'!$C$85:$C$133,'Q4 Assumptions'!$D$85:$D$133,'Q4 Assumptions'!$A$45,'Q4 Assumptions'!$B$85:$B$133,">="&K$10,'Q4 Assumptions'!$B$85:$B$133,"<="&K$11) | ... Q25: ='Q4 Assumptions'!$G$45*Q$12+SUMIFS('Q4 Assumptions'!$C$85:$C$133,'Q4 Assumptions'!$D$85:$D$133,'Q4 Assumptions'!$A$45,'Q4 Assumptions'!$B$85:$B$133,">="&Q$10,'Q4 Assumptions'!$B$85:$B$133,"<="&Q$11) | R25: =SUM(D25:Q25)
B26: Marketing | C26: ='Q4 Assumptions'!C46 | D26: ='Q4 Assumptions'!$G$46*D$12+SUMIFS('Q4 Assumptions'!$C$85:$C$133,'Q4 Assumptions'!$D$85:$D$133,'Q4 Assumptions'!$A$46,'Q4 Assumptions'!$B$85:$B$133,">="&D$10,'Q4 Assumptions'!$B$85:$B$133,"<="&D$11) | E26: ='Q4 Assumptions'!$G$46*E$12+SUMIFS('Q4 Assumptions'!$C$85:$C$133,'Q4 Assumptions'!$D$85:$D$133,'Q4 Assumptions'!$A$46,'Q4 Assumptions'!$B$85:$B$133,">="&E$10,'Q4 Assumptions'!$B$85:$B$133,"<="&E$11) | F26: ='Q4 Assumptions'!$G$46*F$12+SUMIFS('Q4 Assumptions'!$C$85:$C$133,'Q4 Assumptions'!$D$85:$D$133,'Q4 Assumptions'!$A$46,'Q4 Assumptions'!$B$85:$B$133,">="&F$10,'Q4 Assumptions'!$B$85:$B$133,"<="&F$11) | G26: ='Q4 Assumptions'!$G$46*G$12+SUMIFS('Q4 Assumptions'!$C$85:$C$133,'Q4 Assumptions'!$D$85:$D$133,'Q4 Assumptions'!$A$46,'Q4 Assumptions'!$B$85:$B$133,">="&G$10,'Q4 Assumptions'!$B$85:$B$133,"<="&G$11) | H26: ='Q4 Assumptions'!$G$46*H$12+SUMIFS('Q4 Assumptions'!$C$85:$C$133,'Q4 Assumptions'!$D$85:$D$133,'Q4 Assumptions'!$A$46,'Q4 Assumptions'!$B$85:$B$133,">="&H$10,'Q4 Assumptions'!$B$85:$B$133,"<="&H$11) | I26: ='Q4 Assumptions'!$G$46*I$12+SUMIFS('Q4 Assumptions'!$C$85:$C$133,'Q4 Assumptions'!$D$85:$D$133,'Q4 Assumptions'!$A$46,'Q4 Assumptions'!$B$85:$B$133,">="&I$10,'Q4 Assumptions'!$B$85:$B$133,"<="&I$11) | J26: ='Q4 Assumptions'!$G$46*J$12+SUMIFS('Q4 Assumptions'!$C$85:$C$133,'Q4 Assumptions'!$D$85:$D$133,'Q4 Assumptions'!$A$46,'Q4 Assumptions'!$B$85:$B$133,">="&J$10,'Q4 Assumptions'!$B$85:$B$133,"<="&J$11) | K26: ='Q4 Assumptions'!$G$46*K$12+SUMIFS('Q4 Assumptions'!$C$85:$C$133,'Q4 Assumptions'!$D$85:$D$133,'Q4 Assumptions'!$A$46,'Q4 Assumptions'!$B$85:$B$133,">="&K$10,'Q4 Assumptions'!$B$85:$B$133,"<="&K$11) | ... Q26: ='Q4 Assumptions'!$G$46*Q$12+SUMIFS('Q4 Assumptions'!$C$85:$C$133,'Q4 Assumptions'!$D$85:$D$133,'Q4 Assumptions'!$A$46,'Q4 Assumptions'!$B$85:$B$133,">="&Q$10,'Q4 Assumptions'!$B$85:$B$133,"<="&Q$11) | R26: =SUM(D26:Q26)
B27: Profit sharing | C27: ='Q4 Assumptions'!C47 | D27: ='Q4 Assumptions'!$G$47*D$12+SUMIFS('Q4 Assumptions'!$C$85:$C$133,'Q4 Assumptions'!$D$85:$D$133,'Q4 Assumptions'!$A$47,'Q4 Assumptions'!$B$85:$B$133,">="&D$10,'Q4 Assumptions'!$B$85:$B$133,"<="&D$11) | E27: ='Q4 Assumptions'!$G$47*E$12+SUMIFS('Q4 Assumptions'!$C$85:$C$133,'Q4 Assumptions'!$D$85:$D$133,'Q4 Assumptions'!$A$47,'Q4 Assumptions'!$B$85:$B$133,">="&E$10,'Q4 Assumptions'!$B$85:$B$133,"<="&E$11) | F27: ='Q4 Assumptions'!$G$47*F$12+SUMIFS('Q4 Assumptions'!$C$85:$C$133,'Q4 Assumptions'!$D$85:$D$133,'Q4 Assumptions'!$A$47,'Q4 Assumptions'!$B$85:$B$133,">="&F$10,'Q4 Assumptions'!$B$85:$B$133,"<="&F$11) | G27: ='Q4 Assumptions'!$G$47*G$12+SUMIFS('Q4 Assumptions'!$C$85:$C$133,'Q4 Assumptions'!$D$85:$D$133,'Q4 Assumptions'!$A$47,'Q4 Assumptions'!$B$85:$B$133,">="&G$10,'Q4 Assumptions'!$B$85:$B$133,"<="&G$11) | H27: ='Q4 Assumptions'!$G$47*H$12+SUMIFS('Q4 Assumptions'!$C$85:$C$133,'Q4 Assumptions'!$D$85:$D$133,'Q4 Assumptions'!$A$47,'Q4 Assumptions'!$B$85:$B$133,">="&H$10,'Q4 Assumptions'!$B$85:$B$133,"<="&H$11) | I27: ='Q4 Assumptions'!$G$47*I$12+SUMIFS('Q4 Assumptions'!$C$85:$C$133,'Q4 Assumptions'!$D$85:$D$133,'Q4 Assumptions'!$A$47,'Q4 Assumptions'!$B$85:$B$133,">="&I$10,'Q4 Assumptions'!$B$85:$B$133,"<="&I$11) | J27: ='Q4 Assumptions'!$G$47*J$12+SUMIFS('Q4 Assumptions'!$C$85:$C$133,'Q4 Assumptions'!$D$85:$D$133,'Q4 Assumptions'!$A$47,'Q4 Assumptions'!$B$85:$B$133,">="&J$10,'Q4 Assumptions'!$B$85:$B$133,"<="&J$11) | K27: ='Q4 Assumptions'!$G$47*K$12+SUMIFS('Q4 Assumptions'!$C$85:$C$133,'Q4 Assumptions'!$D$85:$D$133,'Q4 Assumptions'!$A$47,'Q4 Assumptions'!$B$85:$B$133,">="&K$10,'Q4 Assumptions'!$B$85:$B$133,"<="&K$11) | ... Q27: ='Q4 Assumptions'!$G$47*Q$12+SUMIFS('Q4 Assumptions'!$C$85:$C$133,'Q4 Assumptions'!$D$85:$D$133,'Q4 Assumptions'!$A$47,'Q4 Assumptions'!$B$85:$B$133,">="&Q$10,'Q4 Assumptions'!$B$85:$B$133,"<="&Q$11) | R27: =SUM(D27:Q27)
B28: Wage expenses | C28: ='Q4 Assumptions'!C48 | D28: ='Q4 Assumptions'!$G$48*D$12+SUMIFS('Q4 Assumptions'!$C$85:$C$133,'Q4 Assumptions'!$D$85:$D$133,'Q4 Assumptions'!$A$48,'Q4 Assumptions'!$B$85:$B$133,">="&D$10,'Q4 Assumptions'!$B$85:$B$133,"<="&D$11)+D85 | E28: ='Q4 Assumptions'!$G$48*E$12+SUMIFS('Q4 Assumptions'!$C$85:$C$133,'Q4 Assumptions'!$D$85:$D$133,'Q4 Assumptions'!$A$48,'Q4 Assumptions'!$B$85:$B$133,">="&E$10,'Q4 Assumptions'!$B$85:$B$133,"<="&E$11)+E85 | F28: ='Q4 Assumptions'!$G$48*F$12+SUMIFS('Q4 Assumptions'!$C$85:$C$133,'Q4 Assumptions'!$D$85:$D$133,'Q4 Assumptions'!$A$48,'Q4 Assumptions'!$B$85:$B$133,">="&F$10,'Q4 Assumptions'!$B$85:$B$133,"<="&F$11)+F85 | G28: ='Q4 Assumptions'!$G$48*G$12+SUMIFS('Q4 Assumptions'!$C$85:$C$133,'Q4 Assumptions'!$D$85:$D$133,'Q4 Assumptions'!$A$48,'Q4 Assumptions'!$B$85:$B$133,">="&G$10,'Q4 Assumptions'!$B$85:$B$133,"<="&G$11)+G85 | H28: ='Q4 Assumptions'!$G$48*H$12+SUMIFS('Q4 Assumptions'!$C$85:$C$133,'Q4 Assumptions'!$D$85:$D$133,'Q4 Assumptions'!$A$48,'Q4 Assumptions'!$B$85:$B$133,">="&H$10,'Q4 Assumptions'!$B$85:$B$133,"<="&H$11)+H85 | I28: ='Q4 Assumptions'!$G$48*I$12+SUMIFS('Q4 Assumptions'!$C$85:$C$133,'Q4 Assumptions'!$D$85:$D$133,'Q4 Assumptions'!$A$48,'Q4 Assumptions'!$B$85:$B$133,">="&I$10,'Q4 Assumptions'!$B$85:$B$133,"<="&I$11)+I85 | J28: ='Q4 Assumptions'!$G$48*J$12+SUMIFS('Q4 Assumptions'!$C$85:$C$133,'Q4 Assumptions'!$D$85:$D$133,'Q4 Assumptions'!$A$48,'Q4 Assumptions'!$B$85:$B$133,">="&J$10,'Q4 Assumptions'!$B$85:$B$133,"<="&J$11)+J85 | K28: ='Q4 Assumptions'!$G$48*K$12+SUMIFS('Q4 Assumptions'!$C$85:$C$133,'Q4 Assumptions'!$D$85:$D$133,'Q4 Assumptions'!$A$48,'Q4 Assumptions'!$B$85:$B$133,">="&K$10,'Q4 Assumptions'!$B$85:$B$133,"<="&K$11)+K85 | ... Q28: ='Q4 Assumptions'!$G$48*Q$12+SUMIFS('Q4 Assumptions'!$C$85:$C$133,'Q4 Assumptions'!$D$85:$D$133,'Q4 Assumptions'!$A$48,'Q4 Assumptions'!$B$85:$B$133,">="&Q$10,'Q4 Assumptions'!$B$85:$B$133,"<="&Q$11)+Q85 | R28: =SUM(D28:Q28)
B29: Bank Charges | C29: ='Q4 Assumptions'!C49 | D29: ='Q4 Assumptions'!$G$49*D$12+SUMIFS('Q4 Assumptions'!$C$85:$C$133,'Q4 Assumptions'!$D$85:$D$133,'Q4 Assumptions'!$A$49,'Q4 Assumptions'!$B$85:$B$133,">="&D$10,'Q4 Assumptions'!$B$85:$B$133,"<="&D$11) | E29: ='Q4 Assumptions'!$G$49*E$12+SUMIFS('Q4 Assumptions'!$C$85:$C$133,'Q4 Assumptions'!$D$85:$D$133,'Q4 Assumptions'!$A$49,'Q4 Assumptions'!$B$85:$B$133,">="&E$10,'Q4 Assumptions'!$B$85:$B$133,"<="&E$11) | F29: ='Q4 Assumptions'!$G$49*F$12+SUMIFS('Q4 Assumptions'!$C$85:$C$133,'Q4 Assumptions'!$D$85:$D$133,'Q4 Assumptions'!$A$49,'Q4 Assumptions'!$B$85:$B$133,">="&F$10,'Q4 Assumptions'!$B$85:$B$133,"<="&F$11) | G29: ='Q4 Assumptions'!$G$49*G$12+SUMIFS('Q4 Assumptions'!$C$85:$C$133,'Q4 Assumptions'!$D$85:$D$133,'Q4 Assumptions'!$A$49,'Q4 Assumptions'!$B$85:$B$133,">="&G$10,'Q4 Assumptions'!$B$85:$B$133,"<="&G$11) | H29: ='Q4 Assumptions'!$G$49*H$12+SUMIFS('Q4 Assumptions'!$C$85:$C$133,'Q4 Assumptions'!$D$85:$D$133,'Q4 Assumptions'!$A$49,'Q4 Assumptions'!$B$85:$B$133,">="&H$10,'Q4 Assumptions'!$B$85:$B$133,"<="&H$11) | I29: ='Q4 Assumptions'!$G$49*I$12+SUMIFS('Q4 Assumptions'!$C$85:$C$133,'Q4 Assumptions'!$D$85:$D$133,'Q4 Assumptions'!$A$49,'Q4 Assumptions'!$B$85:$B$133,">="&I$10,'Q4 Assumptions'!$B$85:$B$133,"<="&I$11) | J29: ='Q4 Assumptions'!$G$49*J$12+SUMIFS('Q4 Assumptions'!$C$85:$C$133,'Q4 Assumptions'!$D$85:$D$133,'Q4 Assumptions'!$A$49,'Q4 Assumptions'!$B$85:$B$133,">="&J$10,'Q4 Assumptions'!$B$85:$B$133,"<="&J$11) | K29: ='Q4 Assumptions'!$G$49*K$12+SUMIFS('Q4 Assumptions'!$C$85:$C$133,'Q4 Assumptions'!$D$85:$D$133,'Q4 Assumptions'!$A$49,'Q4 Assumptions'!$B$85:$B$133,">="&K$10,'Q4 Assumptions'!$B$85:$B$133,"<="&K$11) | ... Q29: ='Q4 Assumptions'!$G$49*Q$12+SUMIFS('Q4 Assumptions'!$C$85:$C$133,'Q4 Assumptions'!$D$85:$D$133,'Q4 Assumptions'!$A$49,'Q4 Assumptions'!$B$85:$B$133,">="&Q$10,'Q4 Assumptions'!$B$85:$B$133,"<="&Q$11) | R29: =SUM(D29:Q29)
B30: Income taxes | C30: ='Q4 Assumptions'!C50 | D30: ='Q4 Assumptions'!$G$50*D$12+SUMIFS('Q4 Assumptions'!$C$85:$C$133,'Q4 Assumptions'!$D$85:$D$133,'Q4 Assumptions'!$A$50,'Q4 Assumptions'!$B$85:$B$133,">="&D$10,'Q4 Assumptions'!$B$85:$B$133,"<="&D$11) | E30: ='Q4 Assumptions'!$G$50*E$12+SUMIFS('Q4 Assumptions'!$C$85:$C$133,'Q4 Assumptions'!$D$85:$D$133,'Q4 Assumptions'!$A$50,'Q4 Assumptions'!$B$85:$B$133,">="&E$10,'Q4 Assumptions'!$B$85:$B$133,"<="&E$11) | F30: ='Q4 Assumptions'!$G$50*F$12+SUMIFS('Q4 Assumptions'!$C$85:$C$133,'Q4 Assumptions'!$D$85:$D$133,'Q4 Assumptions'!$A$50,'Q4 Assumptions'!$B$85:$B$133,">="&F$10,'Q4 Assumptions'!$B$85:$B$133,"<="&F$11) | G30: ='Q4 Assumptions'!$G$50*G$12+SUMIFS('Q4 Assumptions'!$C$85:$C$133,'Q4 Assumptions'!$D$85:$D$133,'Q4 Assumptions'!$A$50,'Q4 Assumptions'!$B$85:$B$133,">="&G$10,'Q4 Assumptions'!$B$85:$B$133,"<="&G$11) | H30: ='Q4 Assumptions'!$G$50*H$12+SUMIFS('Q4 Assumptions'!$C$85:$C$133,'Q4 Assumptions'!$D$85:$D$133,'Q4 Assumptions'!$A$50,'Q4 Assumptions'!$B$85:$B$133,">="&H$10,'Q4 Assumptions'!$B$85:$B$133,"<="&H$11) | I30: ='Q4 Assumptions'!$G$50*I$12+SUMIFS('Q4 Assumptions'!$C$85:$C$133,'Q4 Assumptions'!$D$85:$D$133,'Q4 Assumptions'!$A$50,'Q4 Assumptions'!$B$85:$B$133,">="&I$10,'Q4 Assumptions'!$B$85:$B$133,"<="&I$11) | J30: ='Q4 Assumptions'!$G$50*J$12+SUMIFS('Q4 Assumptions'!$C$85:$C$133,'Q4 Assumptions'!$D$85:$D$133,'Q4 Assumptions'!$A$50,'Q4 Assumptions'!$B$85:$B$133,">="&J$10,'Q4 Assumptions'!$B$85:$B$133,"<="&J$11) | K30: ='Q4 Assumptions'!$G$50*K$12+SUMIFS('Q4 Assumptions'!$C$85:$C$133,'Q4 Assumptions'!$D$85:$D$133,'Q4 Assumptions'!$A$50,'Q4 Assumptions'!$B$85:$B$133,">="&K$10,'Q4 Assumptions'!$B$85:$B$133,"<="&K$11) | ... Q30: ='Q4 Assumptions'!$G$50*Q$12+SUMIFS('Q4 Assumptions'!$C$85:$C$133,'Q4 Assumptions'!$D$85:$D$133,'Q4 Assumptions'!$A$50,'Q4 Assumptions'!$B$85:$B$133,">="&Q$10,'Q4 Assumptions'!$B$85:$B$133,"<="&Q$11) | R30: =SUM(D30:Q30)
B31: New Branches Expenses | C31: ='Q4 Assumptions'!C51 | D31: ='Q4 Assumptions'!$G$51*D$12+SUMIFS('Q4 Assumptions'!$C$85:$C$133,'Q4 Assumptions'!$D$85:$D$133,'Q4 Assumptions'!$A$51,'Q4 Assumptions'!$B$85:$B$133,">="&D$10,'Q4 Assumptions'!$B$85:$B$133,"<="&D$11) | E31: ='Q4 Assumptions'!$G$51*E$12+SUMIFS('Q4 Assumptions'!$C$85:$C$133,'Q4 Assumptions'!$D$85:$D$133,'Q4 Assumptions'!$A$51,'Q4 Assumptions'!$B$85:$B$133,">="&E$10,'Q4 Assumptions'!$B$85:$B$133,"<="&E$11) | F31: ='Q4 Assumptions'!$G$51*F$12+SUMIFS('Q4 Assumptions'!$C$85:$C$133,'Q4 Assumptions'!$D$85:$D$133,'Q4 Assumptions'!$A$51,'Q4 Assumptions'!$B$85:$B$133,">="&F$10,'Q4 Assumptions'!$B$85:$B$133,"<="&F$11) | G31: ='Q4 Assumptions'!$G$51*G$12+SUMIFS('Q4 Assumptions'!$C$85:$C$133,'Q4 Assumptions'!$D$85:$D$133,'Q4 Assumptions'!$A$51,'Q4 Assumptions'!$B$85:$B$133,">="&G$10,'Q4 Assumptions'!$B$85:$B$133,"<="&G$11) | H31: ='Q4 Assumptions'!$G$51*H$12+SUMIFS('Q4 Assumptions'!$C$85:$C$133,'Q4 Assumptions'!$D$85:$D$133,'Q4 Assumptions'!$A$51,'Q4 Assumptions'!$B$85:$B$133,">="&H$10,'Q4 Assumptions'!$B$85:$B$133,"<="&H$11) | I31: ='Q4 Assumptions'!$G$51*I$12+SUMIFS('Q4 Assumptions'!$C$85:$C$133,'Q4 Assumptions'!$D$85:$D$133,'Q4 Assumptions'!$A$51,'Q4 Assumptions'!$B$85:$B$133,">="&I$10,'Q4 Assumptions'!$B$85:$B$133,"<="&I$11) | J31: ='Q4 Assumptions'!$G$51*J$12+SUMIFS('Q4 Assumptions'!$C$85:$C$133,'Q4 Assumptions'!$D$85:$D$133,'Q4 Assumptions'!$A$51,'Q4 Assumptions'!$B$85:$B$133,">="&J$10,'Q4 Assumptions'!$B$85:$B$133,"<="&J$11) | K31: ='Q4 Assumptions'!$G$51*K$12+SUMIFS('Q4 Assumptions'!$C$85:$C$133,'Q4 Assumptions'!$D$85:$D$133,'Q4 Assumptions'!$A$51,'Q4 Assumptions'!$B$85:$B$133,">="&K$10,'Q4 Assumptions'!$B$85:$B$133,"<="&K$11) | ... Q31: ='Q4 Assumptions'!$G$51*Q$12+SUMIFS('Q4 Assumptions'!$C$85:$C$133,'Q4 Assumptions'!$D$85:$D$133,'Q4 Assumptions'!$A$51,'Q4 Assumptions'!$B$85:$B$133,">="&Q$10,'Q4 Assumptions'!$B$85:$B$133,"<="&Q$11) | R31: =SUM(D31:Q31)
B32: Branch Expenditure & Upkeep | C32: ='Q4 Assumptions'!C52 | D32: ='Q4 Assumptions'!$G$52*D$12+SUMIFS('Q4 Assumptions'!$C$85:$C$133,'Q4 Assumptions'!$D$85:$D$133,'Q4 Assumptions'!$A$52,'Q4 Assumptions'!$B$85:$B$133,">="&D$10,'Q4 Assumptions'!$B$85:$B$133,"<="&D$11)+D86 | E32: ='Q4 Assumptions'!$G$52*E$12+SUMIFS('Q4 Assumptions'!$C$85:$C$133,'Q4 Assumptions'!$D$85:$D$133,'Q4 Assumptions'!$A$52,'Q4 Assumptions'!$B$85:$B$133,">="&E$10,'Q4 Assumptions'!$B$85:$B$133,"<="&E$11)+E86 | F32: ='Q4 Assumptions'!$G$52*F$12+SUMIFS('Q4 Assumptions'!$C$85:$C$133,'Q4 Assumptions'!$D$85:$D$133,'Q4 Assumptions'!$A$52,'Q4 Assumptions'!$B$85:$B$133,">="&F$10,'Q4 Assumptions'!$B$85:$B$133,"<="&F$11)+F86 | G32: ='Q4 Assumptions'!$G$52*G$12+SUMIFS('Q4 Assumptions'!$C$85:$C$133,'Q4 Assumptions'!$D$85:$D$133,'Q4 Assumptions'!$A$52,'Q4 Assumptions'!$B$85:$B$133,">="&G$10,'Q4 Assumptions'!$B$85:$B$133,"<="&G$11)+G86 | H32: ='Q4 Assumptions'!$G$52*H$12+SUMIFS('Q4 Assumptions'!$C$85:$C$133,'Q4 Assumptions'!$D$85:$D$133,'Q4 Assumptions'!$A$52,'Q4 Assumptions'!$B$85:$B$133,">="&H$10,'Q4 Assumptions'!$B$85:$B$133,"<="&H$11)+H86 | I32: ='Q4 Assumptions'!$G$52*I$12+SUMIFS('Q4 Assumptions'!$C$85:$C$133,'Q4 Assumptions'!$D$85:$D$133,'Q4 Assumptions'!$A$52,'Q4 Assumptions'!$B$85:$B$133,">="&I$10,'Q4 Assumptions'!$B$85:$B$133,"<="&I$11)+I86 | J32: ='Q4 Assumptions'!$G$52*J$12+SUMIFS('Q4 Assumptions'!$C$85:$C$133,'Q4 Assumptions'!$D$85:$D$133,'Q4 Assumptions'!$A$52,'Q4 Assumptions'!$B$85:$B$133,">="&J$10,'Q4 Assumptions'!$B$85:$B$133,"<="&J$11)+J86 | K32: ='Q4 Assumptions'!$G$52*K$12+SUMIFS('Q4 Assumptions'!$C$85:$C$133,'Q4 Assumptions'!$D$85:$D$133,'Q4 Assumptions'!$A$52,'Q4 Assumptions'!$B$85:$B$133,">="&K$10,'Q4 Assumptions'!$B$85:$B$133,"<="&K$11)+K86 | ... Q32: ='Q4 Assumptions'!$G$52*Q$12+SUMIFS('Q4 Assumptions'!$C$85:$C$133,'Q4 Assumptions'!$D$85:$D$133,'Q4 Assumptions'!$A$52,'Q4 Assumptions'!$B$85:$B$133,">="&Q$10,'Q4 Assumptions'!$B$85:$B$133,"<="&Q$11)+Q86 | R32: =SUM(D32:Q32)
B33: Credit Card | C33: ='Q4 Assumptions'!C53 | D33: ='Q4 Assumptions'!$G$53*D$12+SUMIFS('Q4 Assumptions'!$C$85:$C$133,'Q4 Assumptions'!$D$85:$D$133,'Q4 Assumptions'!$A$53,'Q4 Assumptions'!$B$85:$B$133,">="&D$10,'Q4 Assumptions'!$B$85:$B$133,"<="&D$11) | E33: ='Q4 Assumptions'!$G$53*E$12+SUMIFS('Q4 Assumptions'!$C$85:$C$133,'Q4 Assumptions'!$D$85:$D$133,'Q4 Assumptions'!$A$53,'Q4 Assumptions'!$B$85:$B$133,">="&E$10,'Q4 Assumptions'!$B$85:$B$133,"<="&E$11) | F33: ='Q4 Assumptions'!$G$53*F$12+SUMIFS('Q4 Assumptions'!$C$85:$C$133,'Q4 Assumptions'!$D$85:$D$133,'Q4 Assumptions'!$A$53,'Q4 Assumptions'!$B$85:$B$133,">="&F$10,'Q4 Assumptions'!$B$85:$B$133,"<="&F$11) | G33: ='Q4 Assumptions'!$G$53*G$12+SUMIFS('Q4 Assumptions'!$C$85:$C$133,'Q4 Assumptions'!$D$85:$D$133,'Q4 Assumptions'!$A$53,'Q4 Assumptions'!$B$85:$B$133,">="&G$10,'Q4 Assumptions'!$B$85:$B$133,"<="&G$11) | H33: ='Q4 Assumptions'!$G$53*H$12+SUMIFS('Q4 Assumptions'!$C$85:$C$133,'Q4 Assumptions'!$D$85:$D$133,'Q4 Assumptions'!$A$53,'Q4 Assumptions'!$B$85:$B$133,">="&H$10,'Q4 Assumptions'!$B$85:$B$133,"<="&H$11) | I33: ='Q4 Assumptions'!$G$53*I$12+SUMIFS('Q4 Assumptions'!$C$85:$C$133,'Q4 Assumptions'!$D$85:$D$133,'Q4 Assumptions'!$A$53,'Q4 Assumptions'!$B$85:$B$133,">="&I$10,'Q4 Assumptions'!$B$85:$B$133,"<="&I$11) | J33: ='Q4 Assumptions'!$G$53*J$12+SUMIFS('Q4 Assumptions'!$C$85:$C$133,'Q4 Assumptions'!$D$85:$D$133,'Q4 Assumptions'!$A$53,'Q4 Assumptions'!$B$85:$B$133,">="&J$10,'Q4 Assumptions'!$B$85:$B$133,"<="&J$11) | K33: ='Q4 Assumptions'!$G$53*K$12+SUMIFS('Q4 Assumptions'!$C$85:$C$133,'Q4 Assumptions'!$D$85:$D$133,'Q4 Assumptions'!$A$53,'Q4 Assumptions'!$B$85:$B$133,">="&K$10,'Q4 Assumptions'!$B$85:$B$133,"<="&K$11) | ... Q33: ='Q4 Assumptions'!$G$53*Q$12+SUMIFS('Q4 Assumptions'!$C$85:$C$133,'Q4 Assumptions'!$D$85:$D$133,'Q4 Assumptions'!$A$53,'Q4 Assumptions'!$B$85:$B$133,">="&Q$10,'Q4 Assumptions'!$B$85:$B$133,"<="&Q$11) | R33: =SUM(D33:Q33)
B34: Open House & Iftar | C34: ='Q4 Assumptions'!C54 | D34: ='Q4 Assumptions'!$G$54*D$12+SUMIFS('Q4 Assumptions'!$C$85:$C$133,'Q4 Assumptions'!$D$85:$D$133,'Q4 Assumptions'!$A$54,'Q4 Assumptions'!$B$85:$B$133,">="&D$10,'Q4 Assumptions'!$B$85:$B$133,"<="&D$11) | E34: ='Q4 Assumptions'!$G$54*E$12+SUMIFS('Q4 Assumptions'!$C$85:$C$133,'Q4 Assumptions'!$D$85:$D$133,'Q4 Assumptions'!$A$54,'Q4 Assumptions'!$B$85:$B$133,">="&E$10,'Q4 Assumptions'!$B$85:$B$133,"<="&E$11) | F34: ='Q4 Assumptions'!$G$54*F$12+SUMIFS('Q4 Assumptions'!$C$85:$C$133,'Q4 Assumptions'!$D$85:$D$133,'Q4 Assumptions'!$A$54,'Q4 Assumptions'!$B$85:$B$133,">="&F$10,'Q4 Assumptions'!$B$85:$B$133,"<="&F$11) | G34: ='Q4 Assumptions'!$G$54*G$12+SUMIFS('Q4 Assumptions'!$C$85:$C$133,'Q4 Assumptions'!$D$85:$D$133,'Q4 Assumptions'!$A$54,'Q4 Assumptions'!$B$85:$B$133,">="&G$10,'Q4 Assumptions'!$B$85:$B$133,"<="&G$11) | H34: ='Q4 Assumptions'!$G$54*H$12+SUMIFS('Q4 Assumptions'!$C$85:$C$133,'Q4 Assumptions'!$D$85:$D$133,'Q4 Assumptions'!$A$54,'Q4 Assumptions'!$B$85:$B$133,">="&H$10,'Q4 Assumptions'!$B$85:$B$133,"<="&H$11) | I34: ='Q4 Assumptions'!$G$54*I$12+SUMIFS('Q4 Assumptions'!$C$85:$C$133,'Q4 Assumptions'!$D$85:$D$133,'Q4 Assumptions'!$A$54,'Q4 Assumptions'!$B$85:$B$133,">="&I$10,'Q4 Assumptions'!$B$85:$B$133,"<="&I$11) | J34: ='Q4 Assumptions'!$G$54*J$12+SUMIFS('Q4 Assumptions'!$C$85:$C$133,'Q4 Assumptions'!$D$85:$D$133,'Q4 Assumptions'!$A$54,'Q4 Assumptions'!$B$85:$B$133,">="&J$10,'Q4 Assumptions'!$B$85:$B$133,"<="&J$11) | K34: ='Q4 Assumptions'!$G$54*K$12+SUMIFS('Q4 Assumptions'!$C$85:$C$133,'Q4 Assumptions'!$D$85:$D$133,'Q4 Assumptions'!$A$54,'Q4 Assumptions'!$B$85:$B$133,">="&K$10,'Q4 Assumptions'!$B$85:$B$133,"<="&K$11) | ... Q34: ='Q4 Assumptions'!$G$54*Q$12+SUMIFS('Q4 Assumptions'!$C$85:$C$133,'Q4 Assumptions'!$D$85:$D$133,'Q4 Assumptions'!$A$54,'Q4 Assumptions'!$B$85:$B$133,">="&Q$10,'Q4 Assumptions'!$B$85:$B$133,"<="&Q$11) | R34: =SUM(D34:Q34)
B35: Co Trip | C35: ='Q4 Assumptions'!C55 | D35: ='Q4 Assumptions'!$G$55*D$12+SUMIFS('Q4 Assumptions'!$C$85:$C$133,'Q4 Assumptions'!$D$85:$D$133,'Q4 Assumptions'!$A$55,'Q4 Assumptions'!$B$85:$B$133,">="&D$10,'Q4 Assumptions'!$B$85:$B$133,"<="&D$11) | E35: ='Q4 Assumptions'!$G$55*E$12+SUMIFS('Q4 Assumptions'!$C$85:$C$133,'Q4 Assumptions'!$D$85:$D$133,'Q4 Assumptions'!$A$55,'Q4 Assumptions'!$B$85:$B$133,">="&E$10,'Q4 Assumptions'!$B$85:$B$133,"<="&E$11) | F35: ='Q4 Assumptions'!$G$55*F$12+SUMIFS('Q4 Assumptions'!$C$85:$C$133,'Q4 Assumptions'!$D$85:$D$133,'Q4 Assumptions'!$A$55,'Q4 Assumptions'!$B$85:$B$133,">="&F$10,'Q4 Assumptions'!$B$85:$B$133,"<="&F$11) | G35: ='Q4 Assumptions'!$G$55*G$12+SUMIFS('Q4 Assumptions'!$C$85:$C$133,'Q4 Assumptions'!$D$85:$D$133,'Q4 Assumptions'!$A$55,'Q4 Assumptions'!$B$85:$B$133,">="&G$10,'Q4 Assumptions'!$B$85:$B$133,"<="&G$11) | H35: ='Q4 Assumptions'!$G$55*H$12+SUMIFS('Q4 Assumptions'!$C$85:$C$133,'Q4 Assumptions'!$D$85:$D$133,'Q4 Assumptions'!$A$55,'Q4 Assumptions'!$B$85:$B$133,">="&H$10,'Q4 Assumptions'!$B$85:$B$133,"<="&H$11) | I35: ='Q4 Assumptions'!$G$55*I$12+SUMIFS('Q4 Assumptions'!$C$85:$C$133,'Q4 Assumptions'!$D$85:$D$133,'Q4 Assumptions'!$A$55,'Q4 Assumptions'!$B$85:$B$133,">="&I$10,'Q4 Assumptions'!$B$85:$B$133,"<="&I$11) | J35: ='Q4 Assumptions'!$G$55*J$12+SUMIFS('Q4 Assumptions'!$C$85:$C$133,'Q4 Assumptions'!$D$85:$D$133,'Q4 Assumptions'!$A$55,'Q4 Assumptions'!$B$85:$B$133,">="&J$10,'Q4 Assumptions'!$B$85:$B$133,"<="&J$11) | K35: ='Q4 Assumptions'!$G$55*K$12+SUMIFS('Q4 Assumptions'!$C$85:$C$133,'Q4 Assumptions'!$D$85:$D$133,'Q4 Assumptions'!$A$55,'Q4 Assumptions'!$B$85:$B$133,">="&K$10,'Q4 Assumptions'!$B$85:$B$133,"<="&K$11) | ... Q35: ='Q4 Assumptions'!$G$55*Q$12+SUMIFS('Q4 Assumptions'!$C$85:$C$133,'Q4 Assumptions'!$D$85:$D$133,'Q4 Assumptions'!$A$55,'Q4 Assumptions'!$B$85:$B$133,">="&Q$10,'Q4 Assumptions'!$B$85:$B$133,"<="&Q$11) | R35: =SUM(D35:Q35)
B36: Utilities | C36: ='Q4 Assumptions'!C56 | D36: ='Q4 Assumptions'!$G$56*D$12+SUMIFS('Q4 Assumptions'!$C$85:$C$133,'Q4 Assumptions'!$D$85:$D$133,'Q4 Assumptions'!$A$56,'Q4 Assumptions'!$B$85:$B$133,">="&D$10,'Q4 Assumptions'!$B$85:$B$133,"<="&D$11) | E36: ='Q4 Assumptions'!$G$56*E$12+SUMIFS('Q4 Assumptions'!$C$85:$C$133,'Q4 Assumptions'!$D$85:$D$133,'Q4 Assumptions'!$A$56,'Q4 Assumptions'!$B$85:$B$133,">="&E$10,'Q4 Assumptions'!$B$85:$B$133,"<="&E$11) | F36: ='Q4 Assumptions'!$G$56*F$12+SUMIFS('Q4 Assumptions'!$C$85:$C$133,'Q4 Assumptions'!$D$85:$D$133,'Q4 Assumptions'!$A$56,'Q4 Assumptions'!$B$85:$B$133,">="&F$10,'Q4 Assumptions'!$B$85:$B$133,"<="&F$11) | G36: ='Q4 Assumptions'!$G$56*G$12+SUMIFS('Q4 Assumptions'!$C$85:$C$133,'Q4 Assumptions'!$D$85:$D$133,'Q4 Assumptions'!$A$56,'Q4 Assumptions'!$B$85:$B$133,">="&G$10,'Q4 Assumptions'!$B$85:$B$133,"<="&G$11) | H36: ='Q4 Assumptions'!$G$56*H$12+SUMIFS('Q4 Assumptions'!$C$85:$C$133,'Q4 Assumptions'!$D$85:$D$133,'Q4 Assumptions'!$A$56,'Q4 Assumptions'!$B$85:$B$133,">="&H$10,'Q4 Assumptions'!$B$85:$B$133,"<="&H$11) | I36: ='Q4 Assumptions'!$G$56*I$12+SUMIFS('Q4 Assumptions'!$C$85:$C$133,'Q4 Assumptions'!$D$85:$D$133,'Q4 Assumptions'!$A$56,'Q4 Assumptions'!$B$85:$B$133,">="&I$10,'Q4 Assumptions'!$B$85:$B$133,"<="&I$11) | J36: ='Q4 Assumptions'!$G$56*J$12+SUMIFS('Q4 Assumptions'!$C$85:$C$133,'Q4 Assumptions'!$D$85:$D$133,'Q4 Assumptions'!$A$56,'Q4 Assumptions'!$B$85:$B$133,">="&J$10,'Q4 Assumptions'!$B$85:$B$133,"<="&J$11) | K36: ='Q4 Assumptions'!$G$56*K$12+SUMIFS('Q4 Assumptions'!$C$85:$C$133,'Q4 Assumptions'!$D$85:$D$133,'Q4 Assumptions'!$A$56,'Q4 Assumptions'!$B$85:$B$133,">="&K$10,'Q4 Assumptions'!$B$85:$B$133,"<="&K$11) | ... Q36: ='Q4 Assumptions'!$G$56*Q$12+SUMIFS('Q4 Assumptions'!$C$85:$C$133,'Q4 Assumptions'!$D$85:$D$133,'Q4 Assumptions'!$A$56,'Q4 Assumptions'!$B$85:$B$133,">="&Q$10,'Q4 Assumptions'!$B$85:$B$133,"<="&Q$11) | R36: =SUM(D36:Q36)
